<mujoco model="Cube 3x3x3">
  <compiler autolimits="true" angle="radian" texturedir="assets"/>
  <option timestep="0.01" integrator="implicitfast"/>
  <size memory="600K"/>
  <visual>
    <global azimuth="180" elevation="-20"/>
    <headlight ambient="0.3 0.3 0.3" diffuse="0.6 0.6 0.6" specular="0 0 0"/>
  </visual>
  <statistic meansize="0.0087" extent="0.1"/>
  <default>
    <geom mass="0.00253704"/>
    <motor ctrlrange="-0.05 0.05"/>
    <default class="cubelet">
      <joint type="ball" armature="0.0001" damping="0.0005" frictionloss="0.001"/>
      <geom type="mesh" condim="1" quat="1 0 0 1" mesh="cubelet"/>
    </default>
    <default class="core">
      <geom type="sphere" contype="0" conaffinity="0" group="4" size="0.01"/>
    </default>
  </default>
  <asset>
    <texture name="white" type="2d" file="white.png"/>
    <texture name="yellow" type="2d" file="yellow.png"/>
    <texture name="red" type="2d" file="red.png"/>
    <texture name="orange" type="2d" file="orange.png"/>
    <texture name="blue" type="2d" file="blue.png"/>
    <texture name="green" type="2d" file="green.png"/>
    <material name="white" texture="white"/>
    <material name="yellow" texture="yellow"/>
    <material name="red" texture="red"/>
    <material name="orange" texture="orange"/>
    <material name="blue" texture="blue"/>
    <material name="green" texture="green"/>
    <mesh name="cubelet" file="cubelet.stl" scale="0.001 0.001 0.001"/>
  </asset>
  <worldbody>
    <light pos="0 0 1"/>
    <body name="core" childclass="cubelet">
      <geom class="core"/>
      <body name="pX">
        <joint name="pX" type="hinge" axis="1 0 0"/>
        <geom material="red" pos="0.019 0 0"/>
      </body>
      <body name="nX">
        <joint name="nX" type="hinge" axis="-1 0 0"/>
        <geom material="orange" pos="-0.019 0 0"/>
      </body>
      <body name="pY">
        <joint name="pY" type="hinge" axis="0 1 0"/>
        <geom material="blue" pos="0 0.019 0"/>
      </body>
      <body name="nY">
        <joint name="nY" type="hinge" axis="0 -1 0"/>
        <geom material="green" pos="0 -0.019 0"/>
      </body>
      <body name="pZ">
        <joint name="pZ" type="hinge" axis="0 0 1"/>
        <geom material="white" pos="0 0 0.019"/>
      </body>
      <body name="nZ">
        <joint name="nZ" type="hinge" axis="0 0 -1"/>
        <geom material="yellow" pos="0 0 -0.019"/>
      </body>
      <body name="pX_pY">
        <joint name="pX_pY"/>
        <geom material="red" pos="0.019 0.019 0"/>
      </body>
      <body name="nY_pX">
        <joint name="nY_pX"/>
        <geom material="red" pos="0.019 -0.019 0"/>
      </body>
      <body name="pX_pZ">
        <joint name="pX_pZ"/>
        <geom material="red" pos="0.019 0 0.019"/>
      </body>
      <body name="nZ_pX">
        <joint name="nZ_pX"/>
        <geom material="red" pos="0.019 0 -0.019"/>
      </body>
      <body name="nX_pY">
        <joint name="nX_pY"/>
        <geom material="orange" pos="-0.019 0.019 0"/>
      </body>
      <body name="nX_nY">
        <joint name="nX_nY"/>
        <geom material="orange" pos="-0.019 -0.019 0"/>
      </body>
      <body name="nX_pZ">
        <joint name="nX_pZ"/>
        <geom material="orange" pos="-0.019 0 0.019"/>
      </body>
      <body name="nX_nZ">
        <joint name="nX_nZ"/>
        <geom material="orange" pos="-0.019 0 -0.019"/>
      </body>
      <body name="pY_pZ">
        <joint name="pY_pZ"/>
        <geom material="blue" pos="0 0.019 0.019"/>
      </body>
      <body name="nZ_pY">
        <joint name="nZ_pY"/>
        <geom material="blue" pos="0 0.019 -0.019"/>
      </body>
      <body name="nY_pZ">
        <joint name="nY_pZ"/>
        <geom material="green" pos="0 -0.019 0.019"/>
      </body>
      <body name="nY_nZ">
        <joint name="nY_nZ"/>
        <geom material="green" pos="0 -0.019 -0.019"/>
      </body>
      <body name="pX_pY_pZ">
        <joint name="pX_pY_pZ"/>
        <geom material="red" pos="0.019 0.019 0.019"/>
      </body>
      <body name="nZ_pX_pY">
        <joint name="nZ_pX_pY"/>
        <geom material="red" pos="0.019 0.019 -0.019"/>
      </body>
      <body name="nY_pX_pZ">
        <joint name="nY_pX_pZ"/>
        <geom material="red" pos="0.019 -0.019 0.019"/>
      </body>
      <body name="nY_nZ_pX">
        <joint name="nY_nZ_pX"/>
        <geom material="red" pos="0.019 -0.019 -0.019"/>
      </body>
      <body name="nX_pY_pZ">
        <joint name="nX_pY_pZ"/>
        <geom material="orange" pos="-0.019 0.019 0.019"/>
      </body>
      <body name="nX_nZ_pY">
        <joint name="nX_nZ_pY"/>
        <geom material="orange" pos="-0.019 0.019 -0.019"/>
      </body>
      <body name="nX_nY_pZ">
        <joint name="nX_nY_pZ"/>
        <geom material="orange" pos="-0.019 -0.019 0.019"/>
      </body>
      <body name="nX_nY_nZ">
        <joint name="nX_nY_nZ"/>
        <geom material="orange" pos="-0.019 -0.019 -0.019"/>
      </body>
    </body>
  </worldbody>
  <actuator>
    <motor name="red" joint="pX"/>
    <motor name="orange" joint="nX"/>
    <motor name="blue" joint="pY"/>
    <motor name="green" joint="nY"/>
    <motor name="white" joint="pZ"/>
    <motor name="yellow" joint="nZ"/>
  </actuator>
</mujoco>
